Traceback (most recent call last):
  File "manage.py", line 10, in <module>
    execute_from_command_line(sys.argv)
  File "/usr/local/lib/python2.7/dist-packages/django/core/management/__init__.py", line 399, in execute_from_command_line
    utility.execute()
  File "/usr/local/lib/python2.7/dist-packages/django/core/management/__init__.py", line 392, in execute
    self.fetch_command(subcommand).run_from_argv(self.argv)
  File "/usr/local/lib/python2.7/dist-packages/django/core/management/base.py", line 242, in run_from_argv
    self.execute(*args, **options.__dict__)
  File "/usr/local/lib/python2.7/dist-packages/django/core/management/base.py", line 285, in execute
    output = self.handle(*args, **options)
  File "/usr/local/lib/python2.7/dist-packages/django/core/management/base.py", line 348, in handle
    app_output = self.handle_app(app, **options)
  File "/usr/local/lib/python2.7/dist-packages/django/core/management/commands/sql.py", line 21, in handle_app
    return '\n'.join(sql_create(app, self.style, connections[options.get('database')]))
  File "/usr/local/lib/python2.7/dist-packages/django/core/management/sql.py", line 30, in sql_create
    tables = connection.introspection.table_names()
  File "/usr/local/lib/python2.7/dist-packages/django/db/backends/__init__.py", line 1222, in table_names
    cursor = self.connection.cursor()
  File "/usr/local/lib/python2.7/dist-packages/django/db/backends/__init__.py", line 160, in cursor
    cursor = self.make_debug_cursor(self._cursor())
  File "/usr/local/lib/python2.7/dist-packages/django/db/backends/__init__.py", line 132, in _cursor
    self.ensure_connection()
  File "/usr/local/lib/python2.7/dist-packages/django/db/backends/__init__.py", line 127, in ensure_connection
    self.connect()
  File "/usr/local/lib/python2.7/dist-packages/django/db/utils.py", line 99, in __exit__
    six.reraise(dj_exc_type, dj_exc_value, traceback)
  File "/usr/local/lib/python2.7/dist-packages/django/db/backends/__init__.py", line 127, in ensure_connection
    self.connect()
  File "/usr/local/lib/python2.7/dist-packages/django/db/backends/__init__.py", line 115, in connect
    self.connection = self.get_new_connection(conn_params)
  File "/usr/local/lib/python2.7/dist-packages/django/db/backends/postgresql_psycopg2/base.py", line 114, in get_new_connection
    return Database.connect(**conn_params)
  File "/usr/lib/python2.7/dist-packages/psycopg2/__init__.py", line 179, in connect
    connection_factory=connection_factory, async=async)
django.db.utils.OperationalError: FATAL:  Peer authentication failed for user "admin"

